/*
Function starts mining and returns
Handles any errors - can there be errors just an invalid or valid proof?
Returns valid proof
Does this handle trigger a new block and adding it to the block chain, or should this be injected into the blockchain class and called
What makes for better encapsulation */
fn start_mining(){
    perform_mathematical_proof();
    todo!()
}

// This function is responsible for handling the mathematical
// TODO: Come up with example algorithm
fn perform_mathematical_proof(){
    todo!()
}